# JavaScript try...catch in Detail

### The try...catch statement in JavaScript is used for handling errors gracefully. It prevents unexpected crashes by capturing errors and executing alternative code when an error occurs.

## 1. Syntax of try...catch

The basic syntax of try...catch is:

    try {
      // Code that may cause an error
    } catch (error) {
      // Code to handle the error
    }

## 2. How try...catch Works

+ The try block contains the code that may throw an 
+ If an error occurs, execution jumps to the catch 
+ The catch block receives the error object, which contains details about the 
+ If no error occurs, the catch block is skipped.

📌 Example:
    
    try {
      let result = undefinedVariable * 10; // ReferenceError: undefinedVariable is not defined
    } catch (error) {
      console.log("An error occurred:", error.message);
    }

📌 Output:

    An error occurred: undefinedVariable is not defined

## 3. The error Object in catch

The error object in catch provides useful information:

    try {
      let result = num.toUpperCase(); // TypeError
    } catch (error) {
      console.log("Error Name:", error.name);
      console.log("Error Message:", error.message);
      console.log("Full Error:", error);
    }

📌 Output:

    Error Name: TypeError
    Error Message: num.toUpperCase is not a function
    Full Error: TypeError: num.toUpperCase is not a function
    
        error.name → Type of error (e.g., TypeError, ReferenceError).
        error.message → Description of the error.
        error.stack → Stack trace (useful for debugging).

## 4. The finally Block

The finally block runs regardless of whether an error occurs. It is used for cleanup operations (e.g., closing files, releasing resources).

📌 Example:

    try {
      console.log("Trying...");
      let result = 10 / 0; // No actual error, but division by zero
    } catch (error) {
      console.log("Error occurred:", error.message);
    } finally {
      console.log("This runs no matter what.");
    }

📌 Output:

    Trying...
    This runs no matter what.

## 5. Using throw to Generate Custom Errors

You can manually throw an error using throw.

📌 Example:

    function divide(a, b) {
      if (b === 0) {
        throw new Error("Cannot divide by zero");
      }
      return a / b;
    }
    
    try {
      console.log(divide(10, 0)); // Throws error
    } catch (error) {
      console.log("Error:", error.message);
    }

📌 Output:

    Error: Cannot divide by zero

## 6. Using Multiple catch Blocks (ES10/ES2019 Feature)

JavaScript does not allow multiple catch blocks, but you can handle errors conditionally inside catch.

📌 Example:
    
    try {
      let arr = new Array(-1); // Throws RangeError
    } catch (error) {
      if (error instanceof TypeError) {
        console.log("Type Error:", error.message);
      } else if (error instanceof RangeError) {
        console.log("Range Error:", error.message);
      } else {
        console.log("Other Error:", error.message);
      }
    }

📌 Output:

    Range Error: Invalid array length

## 7. try...catch and Asynchronous Code

try...catch does not work with asynchronous operations like setTimeout() or fetch(). You need to handle errors inside the asynchronous function or use .catch() with promises.

📌 Incorrect Example (Does Not Catch Error)
    
    try {
      setTimeout(() => {
        let result = num * 10; // num is undefined
      }, 1000);
    } catch (error) {
      console.log("Error caught:", error.message); // ❌ This won't execute
    }

📌 Correct Example (Handle Inside Callback)

    setTimeout(() => {
      try {
        let result = num * 10; // num is undefined
      } catch (error) {
        console.log("Error caught:", error.message); // ✅ Error handled here
      }
    }, 1000);

📌 Using try...catch with async/await

    async function fetchData() {
      try {
        let response = await fetch("https://invalid-url.com"); // Throws error
        let data = await response.json();
        console.log(data);
      } catch (error) {
        console.log("Error fetching data:", error.message);
      }
    }
    
    fetchData();

📌 Output:

Error fetching data: Failed to fetch

## 8. Best Practices for Using try...catch

✅ Use try...catch only where errors are expected.
🚫 Don't wrap all code in try...catch—this hides bugs.

✅ Use specific error handling.
🚫 Avoid generic catch blocks that don’t analyze error.name.

✅ Use finally for cleanup.
🚫 Don’t rely on catch for finalizing resources.

✅ Handle asynchronous errors correctly.
🚫 Don’t expect try...catch to work with promises unless used with await.


## 9. Summary
Feature	Description
+ try	Contains code that may throw an error.
+ catch(error)	Handles the error, provides details via the error object.
+ finally	Executes code regardless of error occurrence.
+ throw	Manually triggers an error.
+ Asynchronous Errors	Use .catch() with Promises or wrap await inside try...catch.
